Workbook

Sheet 说明
A1: 国创光谷上城 二手房成交数据整理（卖房参考）
A3: 数据来源 | B3: 用户提供的 20 张经纪 App 成交记录截图（截图时间 2026-09-30），共 80 条，成交日期 2025-02-16 至 2026-09-10。
A4: 字段口径 | B4: 户型「3-2-1-2」= 3室2厅1厨2卫；楼层仅有高/中/低三段，截图未给具体层数；单价为平台显示值，另列按 总价÷面积 的核算值做校验（3 条有 2~7 元尾差，属平台四舍五入或面积小数位差异）。
A5: 状态 | B5: 「已成交」= 已签约未过户（2 条，均为 2026 年 9 月前后）；其余为「已过户」。第 11 张截图顶部 1 条的标签被截断，按已过户记。
A6: 可能遗漏 | B6: 截图之间疑似有未截到的记录：2025-07-20 至 2025-09-09 之间（2025 年 8 月无记录）、2025-04-06 至 2025-05-25 之间；2026 年 2 月无记录（可能是春节淡季）。统计结论按 80 条样本，存在样本偏差。
A7: 首图观感 | B7: 按列表缩略图目测：有装修 / 毛坯 / 空房(不明) / 户型图 / 无图。仅供参考，不代表实际交付标准。
A8: 颜色约定 | B8: 蓝字黄底 = 可修改的假设或参数；黑字 = 公式；绿字 = 引用其他工作表。所有统计与测算均为公式，修改明细或参数后自动重算。
A9: 工作表 | B9: 成交明细 → 季度走势 → 分面积段对比 → 本案估值（110㎡/中楼层/南北通透）→ 持有vs出售测算
A10: 免责声明 | B10: 本表仅为基于公开成交记录的整理与测算，不构成投资、税务或法律建议；税费、贷款、政策以武汉市不动产登记与税务部门最新口径为准。

Sheet 成交明细
A1: 序号 | B1: 截图编号 | C1: 状态 | D1: 成交日期 | E1: 年份 | F1: 季度 | G1: 半年 | H1: 户型(原始) | I1: 室 | J1: 厅 | K1: 厨 | L1: 卫 | M1: 户型 | N1: 建筑面积(㎡) | O1: 面积段 | P1: 楼层段 | Q1: 总层数 | R1: 朝向 | S1: 南北通透 | T1: 首图观感(目测) | U1: 成交总价(万元) | V1: 平台单价(元/㎡) | W1: 核算单价(元/㎡) | X1: 单价尾差 | Y1: 本案可比样本
A2: 1 | B2: 1 | C2: 已成交 | D2: 46275 | E2: =YEAR(D2) -> 2026 | F2: =YEAR(D2)&"Q"&ROUNDUP(MONTH(D2)/3,0) -> 2026Q3 | G2: =YEAR(D2)&"H"&IF(MONTH(D2)<=6,1,2) -> 2026H2 | H2: 3-2-1-2 | I2: 3 | J2: 2 | K2: 1 | L2: 2 | M2: =I2&"室"&J2&"厅"&L2&"卫" -> 3室2厅2卫 | N2: 113.37 | O2: =IF(N2<60,"60㎡以下",IF(N2<90,"75-77㎡",IF(N2<100,"94-97㎡",IF(N2<120,"106-117㎡",IF(N2<150,"124㎡","150㎡以上"))))) -> 106-117㎡ | P2: 高 | Q2: 33 | R2: 东南 | S2: =IF(AND(ISNUMBER(SEARCH("南",R2)),ISNUMBER(SEARCH("北",R2))),"是","否") -> 否 | T2: 有装修 | U2: 137 | V2: 12084 | W2: =ROUND(U2*10000/N2,0) -> 12084 | X2: =W2-V2 -> 0 | Y2: =IF(AND(I2=3,N2>=本案估值!$C$7,N2<=本案估值!$C$8,D2>=本案估值!$C$9),"是","否") -> 是
A3: 2 | B3: 1 | C3: 已过户 | D3: 46269 | E3: =YEAR(D3) -> 2026 | F3: =YEAR(D3)&"Q"&ROUNDUP(MONTH(D3)/3,0) -> 2026Q3 | G3: =YEAR(D3)&"H"&IF(MONTH(D3)<=6,1,2) -> 2026H2 | H3: 2-1-1-1 | I3: 2 | J3: 1 | K3: 1 | L3: 1 | M3: =I3&"室"&J3&"厅"&L3&"卫" -> 2室1厅1卫 | N3: 76.1 | O3: =IF(N3<60,"60㎡以下",IF(N3<90,"75-77㎡",IF(N3<100,"94-97㎡",IF(N3<120,"106-117㎡",IF(N3<150,"124㎡","150㎡以上"))))) -> 75-77㎡ | P3: 高 | Q3: 33 | R3: 南 | S3: =IF(AND(ISNUMBER(SEARCH("南",R3)),ISNUMBER(SEARCH("北",R3))),"是","否") -> 否 | T3: 有装修 | U3: 81 | V3: 10644 | W3: =ROUND(U3*10000/N3,0) -> 10644 | X3: =W3-V3 -> 0 | Y3: =IF(AND(I3=3,N3>=本案估值!$C$7,N3<=本案估值!$C$8,D3>=本案估值!$C$9),"是","否") -> 否
A4: 3 | B4: 1 | C4: 已成交 | D4: 46262 | E4: =YEAR(D4) -> 2026 | F4: =YEAR(D4)&"Q"&ROUNDUP(MONTH(D4)/3,0) -> 2026Q3 | G4: =YEAR(D4)&"H"&IF(MONTH(D4)<=6,1,2) -> 2026H2 | H4: 3-2-1-2 | I4: 3 | J4: 2 | K4: 1 | L4: 2 | M4: =I4&"室"&J4&"厅"&L4&"卫" -> 3室2厅2卫 | N4: 109.99 | O4: =IF(N4<60,"60㎡以下",IF(N4<90,"75-77㎡",IF(N4<100,"94-97㎡",IF(N4<120,"106-117㎡",IF(N4<150,"124㎡","150㎡以上"))))) -> 106-117㎡ | P4: 中 | Q4: 33 | R4: 南 | S4: =IF(AND(ISNUMBER(SEARCH("南",R4)),ISNUMBER(SEARCH("北",R4))),"是","否") -> 否 | T4: 有装修 | U4: 140 | V4: 12728 | W4: =ROUND(U4*10000/N4,0) -> 12728 | X4: =W4-V4 -> 0 | Y4: =IF(AND(I4=3,N4>=本案估值!$C$7,N4<=本案估值!$C$8,D4>=本案估值!$C$9),"是","否") -> 是
A5: 4 | B5: 1 | C5: 已过户 | D5: 46261 | E5: =YEAR(D5) -> 2026 | F5: =YEAR(D5)&"Q"&ROUNDUP(MONTH(D5)/3,0) -> 2026Q3 | G5: =YEAR(D5)&"H"&IF(MONTH(D5)<=6,1,2) -> 2026H2 | H5: 3-2-1-2 | I5: 3 | J5: 2 | K5: 1 | L5: 2 | M5: =I5&"室"&J5&"厅"&L5&"卫" -> 3室2厅2卫 | N5: 115.97 | O5: =IF(N5<60,"60㎡以下",IF(N5<90,"75-77㎡",IF(N5<100,"94-97㎡",IF(N5<120,"106-117㎡",IF(N5<150,"124㎡","150㎡以上"))))) -> 106-117㎡ | P5: 低 | Q5: 33 | R5: 南,南,北 | S5: =IF(AND(ISNUMBER(SEARCH("南",R5)),ISNUMBER(SEARCH("北",R5))),"是","否") -> 是 | T5: 有装修 | U5: 145 | V5: 12503 | W5: =ROUND(U5*10000/N5,0) -> 12503 | X5: =W5-V5 -> 0 | Y5: =IF(AND(I5=3,N5>=本案估值!$C$7,N5<=本案估值!$C$8,D5>=本案估值!$C$9),"是","否") -> 是
A6: 5 | B6: 2 | C6: 已过户 | D6: 46259 | E6: =YEAR(D6) -> 2026 | F6: =YEAR(D6)&"Q"&ROUNDUP(MONTH(D6)/3,0) -> 2026Q3 | G6: =YEAR(D6)&"H"&IF(MONTH(D6)<=6,1,2) -> 2026H2 | H6: 3-2-1-2 | I6: 3 | J6: 2 | K6: 1 | L6: 2 | M6: =I6&"室"&J6&"厅"&L6&"卫" -> 3室2厅2卫 | N6: 109.99 | O6: =IF(N6<60,"60㎡以下",IF(N6<90,"75-77㎡",IF(N6<100,"94-97㎡",IF(N6<120,"106-117㎡",IF(N6<150,"124㎡","150㎡以上"))))) -> 106-117㎡ | P6: 高 | Q6: 33 | R6: 南 | S6: =IF(AND(ISNUMBER(SEARCH("南",R6)),ISNUMBER(SEARCH("北",R6))),"是","否") -> 否 | T6: 户型图 | U6: 124 | V6: 11272 | W6: =ROUND(U6*10000/N6,0) -> 11274 | X6: =W6-V6 -> 2 | Y6: =IF(AND(I6=3,N6>=本案估值!$C$7,N6<=本案估值!$C$8,D6>=本案估值!$C$9),"是","否") -> 是
A7: 6 | B7: 2 | C7: 已过户 | D7: 46259 | E7: =YEAR(D7) -> 2026 | F7: =YEAR(D7)&"Q"&ROUNDUP(MONTH(D7)/3,0) -> 2026Q3 | G7: =YEAR(D7)&"H"&IF(MONTH(D7)<=6,1,2) -> 2026H2 | H7: 3-2-1-1 | I7: 3 | J7: 2 | K7: 1 | L7: 1 | M7: =I7&"室"&J7&"厅"&L7&"卫" -> 3室2厅1卫 | N7: 96 | O7: =IF(N7<60,"60㎡以下",IF(N7<90,"75-77㎡",IF(N7<100,"94-97㎡",IF(N7<120,"106-117㎡",IF(N7<150,"124㎡","150㎡以上"))))) -> 94-97㎡ | P7: 低 | Q7: 33 | R7: 南 | S7: =IF(AND(ISNUMBER(SEARCH("南",R7)),ISNUMBER(SEARCH("北",R7))),"是","否") -> 否 | T7: 无图 | U7: 113.8 | V7: 11854 | W7: =ROUND(U7*10000/N7,0) -> 11854 | X7: =W7-V7 -> 0 | Y7: =IF(AND(I7=3,N7>=本案估值!$C$7,N7<=本案估值!$C$8,D7>=本案估值!$C$9),"是","否") -> 否
A8: 7 | B8: 2 | C8: 已过户 | D8: 46258 | E8: =YEAR(D8) -> 2026 | F8: =YEAR(D8)&"Q"&ROUNDUP(MONTH(D8)/3,0) -> 2026Q3 | G8: =YEAR(D8)&"H"&IF(MONTH(D8)<=6,1,2) -> 2026H2 | H8: 4-1-1-2 | I8: 4 | J8: 1 | K8: 1 | L8: 2 | M8: =I8&"室"&J8&"厅"&L8&"卫" -> 4室1厅2卫 | N8: 163.87 | O8: =IF(N8<60,"60㎡以下",IF(N8<90,"75-77㎡",IF(N8<100,"94-97㎡",IF(N8<120,"106-117㎡",IF(N8<150,"124㎡","150㎡以上"))))) -> 150㎡以上 | P8: 低 | Q8: 11 | R8: 东南 | S8: =IF(AND(ISNUMBER(SEARCH("南",R8)),ISNUMBER(SEARCH("北",R8))),"是","否") -> 否 | T8: 毛坯 | U8: 232 | V8: 14158 | W8: =ROUND(U8*10000/N8,0) -> 14158 | X8: =W8-V8 -> 0 | Y8: =IF(AND(I8=3,N8>=本案估值!$C$7,N8<=本案估值!$C$8,D8>=本案估值!$C$9),"是","否") -> 否
A9: 8 | B9: 2 | C9: 已过户 | D9: 46252 | E9: =YEAR(D9) -> 2026 | F9: =YEAR(D9)&"Q"&ROUNDUP(MONTH(D9)/3,0) -> 2026Q3 | G9: =YEAR(D9)&"H"&IF(MONTH(D9)<=6,1,2) -> 2026H2 | H9: 2-2-1-1 | I9: 2 | J9: 2 | K9: 1 | L9: 1 | M9: =I9&"室"&J9&"厅"&L9&"卫" -> 2室2厅1卫 | N9: 76.1 | O9: =IF(N9<60,"60㎡以下",IF(N9<90,"75-77㎡",IF(N9<100,"94-97㎡",IF(N9<120,"106-117㎡",IF(N9<150,"124㎡","150㎡以上"))))) -> 75-77㎡ | P9: 中 | Q9: 33 | R9: 南 | S9: =IF(AND(ISNUMBER(SEARCH("南",R9)),ISNUMBER(SEARCH("北",R9))),"是","否") -> 否 | T9: 户型图 | U9: 98.8 | V9: 12983 | W9: =ROUND(U9*10000/N9,0) -> 12983 | X9: =W9-V9 -> 0 | Y9: =IF(AND(I9=3,N9>=本案估值!$C$7,N9<=本案估值!$C$8,D9>=本案估值!$C$9),"是","否") -> 否
A10: 9 | B10: 3 | C10: 已过户 | D10: 46250 | E10: =YEAR(D10) -> 2026 | F10: =YEAR(D10)&"Q"&ROUNDUP(MONTH(D10)/3,0) -> 2026Q3 | G10: =YEAR(D10)&"H"&IF(MONTH(D10)<=6,1,2) -> 2026H2 | H10: 3-2-1-1 | I10: 3 | J10: 2 | K10: 1 | L10: 1 | M10: =I10&"室"&J10&"厅"&L10&"卫" -> 3室2厅1卫 | N10: 96.39 | O10: =IF(N10<60,"60㎡以下",IF(N10<90,"75-77㎡",IF(N10<100,"94-97㎡",IF(N10<120,"106-117㎡",IF(N10<150,"124㎡","150㎡以上"))))) -> 94-97㎡ | P10: 中 | Q10: 33 | R10: 南 | S10: =IF(AND(ISNUMBER(SEARCH("南",R10)),ISNUMBER(SEARCH("北",R10))),"是","否") -> 否 | T10: 有装修 | U10: 123 | V10: 12761 | W10: =ROUND(U10*10000/N10,0) -> 12761 | X10: =W10-V10 -> 0 | Y10: =IF(AND(I10=3,N10>=本案估值!$C$7,N10<=本案估值!$C$8,D10>=本案估值!$C$9),"是","否") -> 否
A11: 10 | B11: 3 | C11: 已过户 | D11: 46242 | E11: =YEAR(D11) -> 2026 | F11: =YEAR(D11)&"Q"&ROUNDUP(MONTH(D11)/3,0) -> 2026Q3 | G11: =YEAR(D11)&"H"&IF(MONTH(D11)<=6,1,2) -> 2026H2 | H11: 2-1-1-1 | I11: 2 | J11: 1 | K11: 1 | L11: 1 | M11: =I11&"室"&J11&"厅"&L11&"卫" -> 2室1厅1卫 | N11: 96.39 | O11: =IF(N11<60,"60㎡以下",IF(N11<90,"75-77㎡",IF(N11<100,"94-97㎡",IF(N11<120,"106-117㎡",IF(N11<150,"124㎡","150㎡以上"))))) -> 94-97㎡ | P11: 中 | Q11: 33 | R11: 南,北 | S11: =IF(AND(ISNUMBER(SEARCH("南",R11)),ISNUMBER(SEARCH("北",R11))),"是","否") -> 是 | T11: 有装修 | U11: 121 | V11: 12553 | W11: =ROUND(U11*10000/N11,0) -> 12553 | X11: =W11-V11 -> 0 | Y11: =IF(AND(I11=3,N11>=本案估值!$C$7,N11<=本案估值!$C$8,D11>=本案估值!$C$9),"是","否") -> 否
A12: 11 | B12: 3 | C12: 已过户 | D12: 46237 | E12: =YEAR(D12) -> 2026 | F12: =YEAR(D12)&"Q"&ROUNDUP(MONTH(D12)/3,0) -> 2026Q3 | G12: =YEAR(D12)&"H"&IF(MONTH(D12)<=6,1,2) -> 2026H2 | H12: 1-1-1-1 | I12: 1 | J12: 1 | K12: 1 | L12: 1 | M12: =I12&"室"&J12&"厅"&L12&"卫" -> 1室1厅1卫 | N12: 46.6 | O12: =IF(N12<60,"60㎡以下",IF(N12<90,"75-77㎡",IF(N12<100,"94-97㎡",IF(N12<120,"106-117㎡",IF(N12<150,"124㎡","150㎡以上"))))) -> 60㎡以下 | P12: 高 | Q12: 22 | R12: 南 | S12: =IF(AND(ISNUMBER(SEARCH("南",R12)),ISNUMBER(SEARCH("北",R12))),"是","否") -> 否 | T12: 毛坯 | U12: 33 | V12: 7082 | W12: =ROUND(U12*10000/N12,0) -> 7082 | X12: =W12-V12 -> 0 | Y12: =IF(AND(I12=3,N12>=本案估值!$C$7,N12<=本案估值!$C$8,D12>=本案估值!$C$9),"是","否") -> 否
A13: 12 | B13: 3 | C13: 已过户 | D13: 46233 | E13: =YEAR(D13) -> 2026 | F13: =YEAR(D13)&"Q"&ROUNDUP(MONTH(D13)/3,0) -> 2026Q3 | G13: =YEAR(D13)&"H"&IF(MONTH(D13)<=6,1,2) -> 2026H2 | H13: 2-2-1-1 | I13: 2 | J13: 2 | K13: 1 | L13: 1 | M13: =I13&"室"&J13&"厅"&L13&"卫" -> 2室2厅1卫 | N13: 75.69 | O13: =IF(N13<60,"60㎡以下",IF(N13<90,"75-77㎡",IF(N13<100,"94-97㎡",IF(N13<120,"106-117㎡",IF(N13<150,"124㎡","150㎡以上"))))) -> 75-77㎡ | P13: 高 | Q13: 33 | R13: 南 | S13: =IF(AND(ISNUMBER(SEARCH("南",R13)),ISNUMBER(SEARCH("北",R13))),"是","否") -> 否 | T13: 有装修 | U13: 81 | V13: 10702 | W13: =ROUND(U13*10000/N13,0) -> 10702 | X13: =W13-V13 -> 0 | Y13: =IF(AND(I13=3,N13>=本案估值!$C$7,N13<=本案估值!$C$8,D13>=本案估值!$C$9),"是","否") -> 否
... A81: 80 | B81: 20 | C81: 已过户 | D81: 45704 | E81: =YEAR(D81) -> 2025 | F81: =YEAR(D81)&"Q"&ROUNDUP(MONTH(D81)/3,0) -> 2025Q1 | G81: =YEAR(D81)&"H"&IF(MONTH(D81)<=6,1,2) -> 2025H1 | H81: 2-2-1-1 | I81: 2 | J81: 2 | K81: 1 | L81: 1 | M81: =I81&"室"&J81&"厅"&L81&"卫" -> 2室2厅1卫 | N81: 75.69 | O81: =IF(N81<60,"60㎡以下",IF(N81<90,"75-77㎡",IF(N81<100,"94-97㎡",IF(N81<120,"106-117㎡",IF(N81<150,"124㎡","150㎡以上"))))) -> 75-77㎡ | P81: 低 | Q81: 33 | R81: 南 | S81: =IF(AND(ISNUMBER(SEARCH("南",R81)),ISNUMBER(SEARCH("北",R81))),"是","否") -> 否 | T81: 空房(不明) | U81: 96 | V81: 12683 | W81: =ROUND(U81*10000/N81,0) -> 12683 | X81: =W81-V81 -> 0 | Y81: =IF(AND(I81=3,N81>=本案估值!$C$7,N81<=本案估值!$C$8,D81>=本案估值!$C$9),"是","否") -> 否

Sheet 季度走势
A1: 季度成交走势（全样本 & 106-117㎡ 三房）
A2: 注：部分季度样本量很小（≤7 套），单套极端值会明显拉动均价，中位数更稳健；2025Q3 仅含 7 月与 9 月记录。
A4: 季度 | B4: 成交套数 | C4: 面积加权均价(元/㎡) | D4: 单价中位数(元/㎡) | E4: 最低单价 | F4: 最高单价 | G4: 较2025Q1 (加权均价) | H4: 106-117㎡ 三房套数 | I4: 106-117㎡ 三房中位数 | J4: 106-117㎡ 较2025Q1
A5: 2025Q1 | B5: =COUNTIFS(成交明细!$F$2:$F$81,A5) -> 7 | C5: =IFERROR(SUMIFS(成交明细!$U$2:$U$81,成交明细!$F$2:$F$81,A5)*10000/SUMIFS(成交明细!$N$2:$N$81,成交明细!$F$2:$F$81,A5),"-") -> 14022.111 | D5: {=IFERROR(MEDIAN(IF(成交明细!$F$2:$F$81=A5,成交明细!$W$2:$W$81)),"-")} -> 13903 | E5: =IFERROR(_xlfn.MINIFS(成交明细!$W$2:$W$81,成交明细!$F$2:$F$81,A5),"-") -> 12683 | F5: =IFERROR(_xlfn.MAXIFS(成交明细!$W$2:$W$81,成交明细!$F$2:$F$81,A5),"-") -> 15683 | G5: =IFERROR(C5/$C$5-1,"-") -> 0 | H5: =COUNTIFS(成交明细!$F$2:$F$81,A5,成交明细!$I$2:$I$81,3,成交明细!$O$2:$O$81,"106-117㎡") -> 2 | I5: {=IFERROR(MEDIAN(IF((成交明细!$F$2:$F$81=A5)*(成交明细!$I$2:$I$81=3)*(成交明细!$O$2:$O$81="106-117㎡"),成交明细!$W$2:$W$81)),"-")} -> 14559 | J5: =IFERROR(I5/$I$5-1,"-") -> 0
A6: 2025Q2 | B6: =COUNTIFS(成交明细!$F$2:$F$81,A6) -> 7 | C6: =IFERROR(SUMIFS(成交明细!$U$2:$U$81,成交明细!$F$2:$F$81,A6)*10000/SUMIFS(成交明细!$N$2:$N$81,成交明细!$F$2:$F$81,A6),"-") -> 13801.247 | D6: {=IFERROR(MEDIAN(IF(成交明细!$F$2:$F$81=A6,成交明细!$W$2:$W$81)),"-")} -> 13874 | E6: =IFERROR(_xlfn.MINIFS(成交明细!$W$2:$W$81,成交明细!$F$2:$F$81,A6),"-") -> 12334 | F6: =IFERROR(_xlfn.MAXIFS(成交明细!$W$2:$W$81,成交明细!$F$2:$F$81,A6),"-") -> 14410 | G6: =IFERROR(C6/$C$5-1,"-") -> -0.01575112 | H6: =COUNTIFS(成交明细!$F$2:$F$81,A6,成交明细!$I$2:$I$81,3,成交明细!$O$2:$O$81,"106-117㎡") -> 3 | I6: {=IFERROR(MEDIAN(IF((成交明细!$F$2:$F$81=A6)*(成交明细!$I$2:$I$81=3)*(成交明细!$O$2:$O$81="106-117㎡"),成交明细!$W$2:$W$81)),"-")} -> 14113 | J6: =IFERROR(I6/$I$5-1,"-") -> -0.030633972
A7: 2025Q3 | B7: =COUNTIFS(成交明细!$F$2:$F$81,A7) -> 7 | C7: =IFERROR(SUMIFS(成交明细!$U$2:$U$81,成交明细!$F$2:$F$81,A7)*10000/SUMIFS(成交明细!$N$2:$N$81,成交明细!$F$2:$F$81,A7),"-") -> 13300.084 | D7: {=IFERROR(MEDIAN(IF(成交明细!$F$2:$F$81=A7,成交明细!$W$2:$W$81)),"-")} -> 13857 | E7: =IFERROR(_xlfn.MINIFS(成交明细!$W$2:$W$81,成交明细!$F$2:$F$81,A7),"-") -> 8043 | F7: =IFERROR(_xlfn.MAXIFS(成交明细!$W$2:$W$81,成交明细!$F$2:$F$81,A7),"-") -> 14519 | G7: =IFERROR(C7/$C$5-1,"-") -> -0.051491995 | H7: =COUNTIFS(成交明细!$F$2:$F$81,A7,成交明细!$I$2:$I$81,3,成交明细!$O$2:$O$81,"106-117㎡") -> 5 | I7: {=IFERROR(MEDIAN(IF((成交明细!$F$2:$F$81=A7)*(成交明细!$I$2:$I$81=3)*(成交明细!$O$2:$O$81="106-117㎡"),成交明细!$W$2:$W$81)),"-")} -> 14113 | J7: =IFERROR(I7/$I$5-1,"-") -> -0.030633972
A8: 2025Q4 | B8: =COUNTIFS(成交明细!$F$2:$F$81,A8) -> 23 | C8: =IFERROR(SUMIFS(成交明细!$U$2:$U$81,成交明细!$F$2:$F$81,A8)*10000/SUMIFS(成交明细!$N$2:$N$81,成交明细!$F$2:$F$81,A8),"-") -> 11473.189 | D8: {=IFERROR(MEDIAN(IF(成交明细!$F$2:$F$81=A8,成交明细!$W$2:$W$81)),"-")} -> 10820 | E8: =IFERROR(_xlfn.MINIFS(成交明细!$W$2:$W$81,成交明细!$F$2:$F$81,A8),"-") -> 9514 | F8: =IFERROR(_xlfn.MAXIFS(成交明细!$W$2:$W$81,成交明细!$F$2:$F$81,A8),"-") -> 14092 | G8: =IFERROR(C8/$C$5-1,"-") -> -0.18177878 | H8: =COUNTIFS(成交明细!$F$2:$F$81,A8,成交明细!$I$2:$I$81,3,成交明细!$O$2:$O$81,"106-117㎡") -> 7 | I8: {=IFERROR(MEDIAN(IF((成交明细!$F$2:$F$81=A8)*(成交明细!$I$2:$I$81=3)*(成交明细!$O$2:$O$81="106-117㎡"),成交明细!$W$2:$W$81)),"-")} -> 12323 | J8: =IFERROR(I8/$I$5-1,"-") -> -0.15358198
A9: 2026Q1 | B9: =COUNTIFS(成交明细!$F$2:$F$81,A9) -> 9 | C9: =IFERROR(SUMIFS(成交明细!$U$2:$U$81,成交明细!$F$2:$F$81,A9)*10000/SUMIFS(成交明细!$N$2:$N$81,成交明细!$F$2:$F$81,A9),"-") -> 11172.447 | D9: {=IFERROR(MEDIAN(IF(成交明细!$F$2:$F$81=A9,成交明细!$W$2:$W$81)),"-")} -> 11074 | E9: =IFERROR(_xlfn.MINIFS(成交明细!$W$2:$W$81,成交明细!$F$2:$F$81,A9),"-") -> 9137 | F9: =IFERROR(_xlfn.MAXIFS(成交明细!$W$2:$W$81,成交明细!$F$2:$F$81,A9),"-") -> 13090 | G9: =IFERROR(C9/$C$5-1,"-") -> -0.20322644 | H9: =COUNTIFS(成交明细!$F$2:$F$81,A9,成交明细!$I$2:$I$81,3,成交明细!$O$2:$O$81,"106-117㎡") -> 4 | I9: {=IFERROR(MEDIAN(IF((成交明细!$F$2:$F$81=A9)*(成交明细!$I$2:$I$81=3)*(成交明细!$O$2:$O$81="106-117㎡"),成交明细!$W$2:$W$81)),"-")} -> 11438.5 | J9: =IFERROR(I9/$I$5-1,"-") -> -0.21433478
A10: 2026Q2 | B10: =COUNTIFS(成交明细!$F$2:$F$81,A10) -> 10 | C10: =IFERROR(SUMIFS(成交明细!$U$2:$U$81,成交明细!$F$2:$F$81,A10)*10000/SUMIFS(成交明细!$N$2:$N$81,成交明细!$F$2:$F$81,A10),"-") -> 11775.711 | D10: {=IFERROR(MEDIAN(IF(成交明细!$F$2:$F$81=A10,成交明细!$W$2:$W$81)),"-")} -> 11650.5 | E10: =IFERROR(_xlfn.MINIFS(成交明细!$W$2:$W$81,成交明细!$F$2:$F$81,A10),"-") -> 9879 | F10: =IFERROR(_xlfn.MAXIFS(成交明细!$W$2:$W$81,成交明细!$F$2:$F$81,A10),"-") -> 13516 | G10: =IFERROR(C10/$C$5-1,"-") -> -0.16020408 | H10: =COUNTIFS(成交明细!$F$2:$F$81,A10,成交明细!$I$2:$I$81,3,成交明细!$O$2:$O$81,"106-117㎡") -> 4 | I10: {=IFERROR(MEDIAN(IF((成交明细!$F$2:$F$81=A10)*(成交明细!$I$2:$I$81=3)*(成交明细!$O$2:$O$81="106-117㎡"),成交明细!$W$2:$W$81)),"-")} -> 11418.5 | J10: =IFERROR(I10/$I$5-1,"-") -> -0.2157085
A11: 2026Q3 | B11: =COUNTIFS(成交明细!$F$2:$F$81,A11) -> 17 | C11: =IFERROR(SUMIFS(成交明细!$U$2:$U$81,成交明细!$F$2:$F$81,A11)*10000/SUMIFS(成交明细!$N$2:$N$81,成交明细!$F$2:$F$81,A11),"-") -> 11972.624 | D11: {=IFERROR(MEDIAN(IF(成交明细!$F$2:$F$81=A11,成交明细!$W$2:$W$81)),"-")} -> 11854 | E11: =IFERROR(_xlfn.MINIFS(成交明细!$W$2:$W$81,成交明细!$F$2:$F$81,A11),"-") -> 7082 | F11: =IFERROR(_xlfn.MAXIFS(成交明细!$W$2:$W$81,成交明细!$F$2:$F$81,A11),"-") -> 14158 | G11: =IFERROR(C11/$C$5-1,"-") -> -0.14616107 | H11: =COUNTIFS(成交明细!$F$2:$F$81,A11,成交明细!$I$2:$I$81,3,成交明细!$O$2:$O$81,"106-117㎡") -> 6 | I11: {=IFERROR(MEDIAN(IF((成交明细!$F$2:$F$81=A11)*(成交明细!$I$2:$I$81=3)*(成交明细!$O$2:$O$81="106-117㎡"),成交明细!$W$2:$W$81)),"-")} -> 12293.5 | J11: =IFERROR(I11/$I$5-1,"-") -> -0.15560821
A13: 半年度汇总
A14: 半年 | B14: 成交套数 | C14: 面积加权均价(元/㎡) | D14: 单价中位数(元/㎡) | E14: 较2025H1 (中位数)
A15: 2025H1 | B15: =COUNTIFS(成交明细!$G$2:$G$81,A15) -> 14 | C15: =IFERROR(SUMIFS(成交明细!$U$2:$U$81,成交明细!$G$2:$G$81,A15)*10000/SUMIFS(成交明细!$N$2:$N$81,成交明细!$G$2:$G$81,A15),"-") -> 13906.966 | D15: {=IFERROR(MEDIAN(IF(成交明细!$G$2:$G$81=A15,成交明细!$W$2:$W$81)),"-")} -> 13888.5 | E15: =IFERROR(D15/$D$15-1,"-") -> 0
A16: 2025H2 | B16: =COUNTIFS(成交明细!$G$2:$G$81,A16) -> 30 | C16: =IFERROR(SUMIFS(成交明细!$U$2:$U$81,成交明细!$G$2:$G$81,A16)*10000/SUMIFS(成交明细!$N$2:$N$81,成交明细!$G$2:$G$81,A16),"-") -> 11914.3 | D16: {=IFERROR(MEDIAN(IF(成交明细!$G$2:$G$81=A16,成交明细!$W$2:$W$81)),"-")} -> 11177.5 | E16: =IFERROR(D16/$D$15-1,"-") -> -0.19519747
A17: 2026H1 | B17: =COUNTIFS(成交明细!$G$2:$G$81,A17) -> 19 | C17: =IFERROR(SUMIFS(成交明细!$U$2:$U$81,成交明细!$G$2:$G$81,A17)*10000/SUMIFS(成交明细!$N$2:$N$81,成交明细!$G$2:$G$81,A17),"-") -> 11499.161 | D17: {=IFERROR(MEDIAN(IF(成交明细!$G$2:$G$81=A17,成交明细!$W$2:$W$81)),"-")} -> 11432 | E17: =IFERROR(D17/$D$15-1,"-") -> -0.17687295
A18: 2026H2 | B18: =COUNTIFS(成交明细!$G$2:$G$81,A18) -> 17 | C18: =IFERROR(SUMIFS(成交明细!$U$2:$U$81,成交明细!$G$2:$G$81,A18)*10000/SUMIFS(成交明细!$N$2:$N$81,成交明细!$G$2:$G$81,A18),"-") -> 11972.624 | D18: {=IFERROR(MEDIAN(IF(成交明细!$G$2:$G$81=A18,成交明细!$W$2:$W$81)),"-")} -> 11854 | E18: =IFERROR(D18/$D$15-1,"-") -> -0.1464881
A19: 2026H2 目前只含 7-9 月。

Sheet 分面积段对比
A1: 分面积段成交单价对比（中位数，元/㎡）
A2: 套数与中位数分列；样本少于 3 套的格子参考价值有限。
A4: 面积段 | B4: 2025H1 套数 | C4: 2025H1 中位数 | D4: 2025H2 套数 | E4: 2025H2 中位数 | F4: 2026H1 套数 | G4: 2026H1 中位数 | H4: 2026H2 套数 | I4: 2026H2 中位数 | J4: 2026H2 较 2025H1
A5: 60㎡以下 | B5: =COUNTIFS(成交明细!$O$2:$O$81,$A5,成交明细!$G$2:$G$81,"2025H1") -> 0 | C5: {=IFERROR(MEDIAN(IF((成交明细!$O$2:$O$81=$A5)*(成交明细!$G$2:$G$81="2025H1"),成交明细!$W$2:$W$81)),"-")} -> - | D5: =COUNTIFS(成交明细!$O$2:$O$81,$A5,成交明细!$G$2:$G$81,"2025H2") -> 1 | E5: {=IFERROR(MEDIAN(IF((成交明细!$O$2:$O$81=$A5)*(成交明细!$G$2:$G$81="2025H2"),成交明细!$W$2:$W$81)),"-")} -> 8043 | F5: =COUNTIFS(成交明细!$O$2:$O$81,$A5,成交明细!$G$2:$G$81,"2026H1") -> 0 | G5: {=IFERROR(MEDIAN(IF((成交明细!$O$2:$O$81=$A5)*(成交明细!$G$2:$G$81="2026H1"),成交明细!$W$2:$W$81)),"-")} -> - | H5: =COUNTIFS(成交明细!$O$2:$O$81,$A5,成交明细!$G$2:$G$81,"2026H2") -> 2 | I5: {=IFERROR(MEDIAN(IF((成交明细!$O$2:$O$81=$A5)*(成交明细!$G$2:$G$81="2026H2"),成交明细!$W$2:$W$81)),"-")} -> 7305.5 | J5: =IFERROR(I5/C5-1,"-") -> -
A6: 75-77㎡ | B6: =COUNTIFS(成交明细!$O$2:$O$81,$A6,成交明细!$G$2:$G$81,"2025H1") -> 6 | C6: {=IFERROR(MEDIAN(IF((成交明细!$O$2:$O$81=$A6)*(成交明细!$G$2:$G$81="2025H1"),成交明细!$W$2:$W$81)),"-")} -> 13916 | D6: =COUNTIFS(成交明细!$O$2:$O$81,$A6,成交明细!$G$2:$G$81,"2025H2") -> 6 | E6: {=IFERROR(MEDIAN(IF((成交明细!$O$2:$O$81=$A6)*(成交明细!$G$2:$G$81="2025H2"),成交明细!$W$2:$W$81)),"-")} -> 10118.5 | F6: =COUNTIFS(成交明细!$O$2:$O$81,$A6,成交明细!$G$2:$G$81,"2026H1") -> 2 | G6: {=IFERROR(MEDIAN(IF((成交明细!$O$2:$O$81=$A6)*(成交明细!$G$2:$G$81="2026H1"),成交明细!$W$2:$W$81)),"-")} -> 11348 | H6: =COUNTIFS(成交明细!$O$2:$O$81,$A6,成交明细!$G$2:$G$81,"2026H2") -> 5 | I6: {=IFERROR(MEDIAN(IF((成交明细!$O$2:$O$81=$A6)*(成交明细!$G$2:$G$81="2026H2"),成交明细!$W$2:$W$81)),"-")} -> 10867 | J6: =IFERROR(I6/C6-1,"-") -> -0.21910032
A7: 94-97㎡ | B7: =COUNTIFS(成交明细!$O$2:$O$81,$A7,成交明细!$G$2:$G$81,"2025H1") -> 3 | C7: {=IFERROR(MEDIAN(IF((成交明细!$O$2:$O$81=$A7)*(成交明细!$G$2:$G$81="2025H1"),成交明细!$W$2:$W$81)),"-")} -> 13776 | D7: =COUNTIFS(成交明细!$O$2:$O$81,$A7,成交明细!$G$2:$G$81,"2025H2") -> 10 | E7: {=IFERROR(MEDIAN(IF((成交明细!$O$2:$O$81=$A7)*(成交明细!$G$2:$G$81="2025H2"),成交明细!$W$2:$W$81)),"-")} -> 10634 | F7: =COUNTIFS(成交明细!$O$2:$O$81,$A7,成交明细!$G$2:$G$81,"2026H1") -> 7 | G7: {=IFERROR(MEDIAN(IF((成交明细!$O$2:$O$81=$A7)*(成交明细!$G$2:$G$81="2026H1"),成交明细!$W$2:$W$81)),"-")} -> 11204 | H7: =COUNTIFS(成交明细!$O$2:$O$81,$A7,成交明细!$G$2:$G$81,"2026H2") -> 3 | I7: {=IFERROR(MEDIAN(IF((成交明细!$O$2:$O$81=$A7)*(成交明细!$G$2:$G$81="2026H2"),成交明细!$W$2:$W$81)),"-")} -> 12553 | J7: =IFERROR(I7/C7-1,"-") -> -0.088777584
A8: 106-117㎡ | B8: =COUNTIFS(成交明细!$O$2:$O$81,$A8,成交明细!$G$2:$G$81,"2025H1") -> 5 | C8: {=IFERROR(MEDIAN(IF((成交明细!$O$2:$O$81=$A8)*(成交明细!$G$2:$G$81="2025H1"),成交明细!$W$2:$W$81)),"-")} -> 14113 | D8: =COUNTIFS(成交明细!$O$2:$O$81,$A8,成交明细!$G$2:$G$81,"2025H2") -> 12 | E8: {=IFERROR(MEDIAN(IF((成交明细!$O$2:$O$81=$A8)*(成交明细!$G$2:$G$81="2025H2"),成交明细!$W$2:$W$81)),"-")} -> 13401 | F8: =COUNTIFS(成交明细!$O$2:$O$81,$A8,成交明细!$G$2:$G$81,"2026H1") -> 8 | G8: {=IFERROR(MEDIAN(IF((成交明细!$O$2:$O$81=$A8)*(成交明细!$G$2:$G$81="2026H1"),成交明细!$W$2:$W$81)),"-")} -> 11438.5 | H8: =COUNTIFS(成交明细!$O$2:$O$81,$A8,成交明细!$G$2:$G$81,"2026H2") -> 6 | I8: {=IFERROR(MEDIAN(IF((成交明细!$O$2:$O$81=$A8)*(成交明细!$G$2:$G$81="2026H2"),成交明细!$W$2:$W$81)),"-")} -> 12293.5 | J8: =IFERROR(I8/C8-1,"-") -> -0.12892369
A9: 124㎡ | B9: =COUNTIFS(成交明细!$O$2:$O$81,$A9,成交明细!$G$2:$G$81,"2025H1") -> 0 | C9: {=IFERROR(MEDIAN(IF((成交明细!$O$2:$O$81=$A9)*(成交明细!$G$2:$G$81="2025H1"),成交明细!$W$2:$W$81)),"-")} -> - | D9: =COUNTIFS(成交明细!$O$2:$O$81,$A9,成交明细!$G$2:$G$81,"2025H2") -> 1 | E9: {=IFERROR(MEDIAN(IF((成交明细!$O$2:$O$81=$A9)*(成交明细!$G$2:$G$81="2025H2"),成交明细!$W$2:$W$81)),"-")} -> 13516 | F9: =COUNTIFS(成交明细!$O$2:$O$81,$A9,成交明细!$G$2:$G$81,"2026H1") -> 2 | G9: {=IFERROR(MEDIAN(IF((成交明细!$O$2:$O$81=$A9)*(成交明细!$G$2:$G$81="2026H1"),成交明细!$W$2:$W$81)),"-")} -> 13234.5 | H9: =COUNTIFS(成交明细!$O$2:$O$81,$A9,成交明细!$G$2:$G$81,"2026H2") -> 0 | I9: {=IFERROR(MEDIAN(IF((成交明细!$O$2:$O$81=$A9)*(成交明细!$G$2:$G$81="2026H2"),成交明细!$W$2:$W$81)),"-")} -> - | J9: =IFERROR(I9/C9-1,"-") -> -
A10: 150㎡以上 | B10: =COUNTIFS(成交明细!$O$2:$O$81,$A10,成交明细!$G$2:$G$81,"2025H1") -> 0 | C10: {=IFERROR(MEDIAN(IF((成交明细!$O$2:$O$81=$A10)*(成交明细!$G$2:$G$81="2025H1"),成交明细!$W$2:$W$81)),"-")} -> - | D10: =COUNTIFS(成交明细!$O$2:$O$81,$A10,成交明细!$G$2:$G$81,"2025H2") -> 0 | E10: {=IFERROR(MEDIAN(IF((成交明细!$O$2:$O$81=$A10)*(成交明细!$G$2:$G$81="2025H2"),成交明细!$W$2:$W$81)),"-")} -> - | F10: =COUNTIFS(成交明细!$O$2:$O$81,$A10,成交明细!$G$2:$G$81,"2026H1") -> 0 | G10: {=IFERROR(MEDIAN(IF((成交明细!$O$2:$O$81=$A10)*(成交明细!$G$2:$G$81="2026H1"),成交明细!$W$2:$W$81)),"-")} -> - | H10: =COUNTIFS(成交明细!$O$2:$O$81,$A10,成交明细!$G$2:$G$81,"2026H2") -> 1 | I10: {=IFERROR(MEDIAN(IF((成交明细!$O$2:$O$81=$A10)*(成交明细!$G$2:$G$81="2026H2"),成交明细!$W$2:$W$81)),"-")} -> 14158 | J10: =IFERROR(I10/C10-1,"-") -> -
A13: 朝向与楼层（仅 106-117㎡ 三房，全时段）
A14: 维度 | B14: 取值 | C14: 套数 | D14: 单价中位数(元/㎡)
A15: 南北通透 | B15: 是 | C15: =COUNTIFS(成交明细!$O$2:$O$81,"106-117㎡",成交明细!$I$2:$I$81,3,成交明细!$S$2:$S$81,B15) -> 9 | D15: {=IFERROR(MEDIAN(IF((成交明细!$O$2:$O$81="106-117㎡")*(成交明细!$I$2:$I$81=3)*(成交明细!$S$2:$S$81=B15),成交明细!$W$2:$W$81)),"-")} -> 12503
A16: 南北通透 | B16: 否 | C16: =COUNTIFS(成交明细!$O$2:$O$81,"106-117㎡",成交明细!$I$2:$I$81,3,成交明细!$S$2:$S$81,B16) -> 22 | D16: {=IFERROR(MEDIAN(IF((成交明细!$O$2:$O$81="106-117㎡")*(成交明细!$I$2:$I$81=3)*(成交明细!$S$2:$S$81=B16),成交明细!$W$2:$W$81)),"-")} -> 12627.5
A17: 楼层段 | B17: 高 | C17: =COUNTIFS(成交明细!$O$2:$O$81,"106-117㎡",成交明细!$I$2:$I$81,3,成交明细!$P$2:$P$81,B17) -> 11 | D17: {=IFERROR(MEDIAN(IF((成交明细!$O$2:$O$81="106-117㎡")*(成交明细!$I$2:$I$81=3)*(成交明细!$P$2:$P$81=B17),成交明细!$W$2:$W$81)),"-")} -> 12227
A18: 楼层段 | B18: 中 | C18: =COUNTIFS(成交明细!$O$2:$O$81,"106-117㎡",成交明细!$I$2:$I$81,3,成交明细!$P$2:$P$81,B18) -> 12 | D18: {=IFERROR(MEDIAN(IF((成交明细!$O$2:$O$81="106-117㎡")*(成交明细!$I$2:$I$81=3)*(成交明细!$P$2:$P$81=B18),成交明细!$W$2:$W$81)),"-")} -> 13151
A19: 楼层段 | B19: 低 | C19: =COUNTIFS(成交明细!$O$2:$O$81,"106-117㎡",成交明细!$I$2:$I$81,3,成交明细!$P$2:$P$81,B19) -> 8 | D19: {=IFERROR(MEDIAN(IF((成交明细!$O$2:$O$81="106-117㎡")*(成交明细!$I$2:$I$81=3)*(成交明细!$P$2:$P$81=B19),成交明细!$W$2:$W$81)),"-")} -> 12355
A21: 注：全时段混合了 2025 年高价期与 2026 年低价期，朝向/楼层差异可能被成交时间差掩盖，只作方向参考。

Sheet 本案估值
A1: 本案估值：110㎡ · 中间楼栋 14/33 层（中楼层）· 南北通透
A2: 黄底蓝字为可调参数。可比样本 = 3室 + 面积区间 + 起始日期之后成交（在「成交明细」Y 列标记）。
B4: 一、本案与可比条件
B5: 本案建筑面积(㎡) | C5: 110 | D5: 用户给定
B6: 本案楼层 | C6: 中（14/33） | D6: 用户给定；小区中间楼栋，通常噪音与视野较好
B7: 可比样本：最小面积(㎡) | C7: 105 | D7: 取 106-117㎡ 大三房（小区 109.99/113.37/115.97/116.04 等户型）
B8: 可比样本：最大面积(㎡) | C8: 117
B9: 可比样本：起始日期 | C9: 46082 | D9: 只取近约 6 个月，反映当前价格水平
B10: 近期窗口起始日期 | C10: 46204 | D10: 用于单独观察最近一个季度
B12: 二、可比样本统计
B13: 可比样本套数 | C13: =COUNTIFS(成交明细!$Y$2:$Y$81,"是") -> 14
B14: 可比单价均值(元/㎡) | C14: =IFERROR(AVERAGEIFS(成交明细!$W$2:$W$81,成交明细!$Y$2:$Y$81,"是"),"-") -> 11640.643
B15: 可比单价中位数(元/㎡) | C15: {=MEDIAN(IF(成交明细!$Y$2:$Y$81="是",成交明细!$W$2:$W$81))} -> 11939.5
B16: 可比单价 25 分位(元/㎡) | C16: {=PERCENTILE(IF(成交明细!$Y$2:$Y$81="是",成交明细!$W$2:$W$81),0.25)} -> 11124
B17: 可比单价 75 分位(元/㎡) | C17: {=PERCENTILE(IF(成交明细!$Y$2:$Y$81="是",成交明细!$W$2:$W$81),0.75)} -> 12405.5
B18: 近期窗口可比套数 | C18: =COUNTIFS(成交明细!$Y$2:$Y$81,"是",成交明细!$D$2:$D$81,">="&C10) -> 6
B19: 近期窗口可比均价(元/㎡) | C19: =IFERROR(AVERAGEIFS(成交明细!$W$2:$W$81,成交明细!$Y$2:$Y$81,"是",成交明细!$D$2:$D$81,">="&C10),"-") -> 12172.667
B21: 三、个性化调整（假设，可改）
B22: 南北通透调整 | C22: 0.01 | D22: 假设值：样本里南北通透与纯南向差异不显著，给小幅溢价
B23: 中楼层/中间楼栋调整 | C23: 0.01 | D23: 假设值：可比样本含较多高/低楼层
B24: 装修状况调整 | C24: 0 | D24: 请按实际填写：精装保养好可 +2%~+4%，毛坯/老旧 -3%~-5%
B25: 合计调整 | C25: =C22+C23+C24 -> 0.02
B27: 四、估值结果
B28: 情形 | C28: 单价(元/㎡) | D28: 总价(万元)
B29: 保守（25 分位） | C29: =IFERROR(ROUND(C16*(1+$C$25),0),"-") -> 11346 | D29: =IFERROR(C29*$C$5/10000,"-") -> 124.806
B30: 中性（中位数） | C30: =IFERROR(ROUND(C15*(1+$C$25),0),"-") -> 12178 | D30: =IFERROR(C30*$C$5/10000,"-") -> 133.958
B31: 乐观（75 分位） | C31: =IFERROR(ROUND(C17*(1+$C$25),0),"-") -> 12654 | D31: =IFERROR(C31*$C$5/10000,"-") -> 139.194
B32: 参考：近期窗口均价 | C32: =IFERROR(ROUND(C19*(1+$C$25),0),"-") -> 12416 | D32: =IFERROR(C32*$C$5/10000,"-") -> 136.576
B34: 五、挂牌策略参考
B35: 挂牌议价空间 | C35: 0.04 | D35: 假设值：挂牌价高于目标成交价的幅度，留给买方砍价
B36: 建议挂牌价(万元) | C36: =ROUND(D30*(1+C35),1) -> 139.3 | D36: 中性估值 ×（1+议价空间）
B37: 目标成交价(万元) | C37: =D30 -> 133.958 | D37: 中性估值
B38: 心理底价(万元) | C38: =D29 -> 124.806 | D38: 保守估值；低于此价需慎重
B40: 六、默认条件下的可比样本（修改条件后请到「成交明细」按 Y 列筛选）
B41: 成交日期 | C41: 面积(㎡) | D41: 楼层段 | E41: 朝向 | F41: 首图观感 | G41: 总价(万元) | H41: 单价(元/㎡)
B42: =成交明细!D2 -> 46275 | C42: =成交明细!N2 -> 113.37 | D42: =成交明细!P2 -> 高 | E42: =成交明细!R2 -> 东南 | F42: =成交明细!T2 -> 有装修 | G42: =成交明细!U2 -> 137 | H42: =成交明细!W2 -> 12084
B43: =成交明细!D4 -> 46262 | C43: =成交明细!N4 -> 109.99 | D43: =成交明细!P4 -> 中 | E43: =成交明细!R4 -> 南 | F43: =成交明细!T4 -> 有装修 | G43: =成交明细!U4 -> 140 | H43: =成交明细!W4 -> 12728
B44: =成交明细!D5 -> 46261 | C44: =成交明细!N5 -> 115.97 | D44: =成交明细!P5 -> 低 | E44: =成交明细!R5 -> 南,南,北 | F44: =成交明细!T5 -> 有装修 | G44: =成交明细!U5 -> 145 | H44: =成交明细!W5 -> 12503
B45: =成交明细!D6 -> 46259 | C45: =成交明细!N6 -> 109.99 | D45: =成交明细!P6 -> 高 | E45: =成交明细!R6 -> 南 | F45: =成交明细!T6 -> 户型图 | G45: =成交明细!U6 -> 124 | H45: =成交明细!W6 -> 11274
B46: =成交明细!D14 -> 46228 | C46: =成交明细!N14 -> 115.97 | D46: =成交明细!P14 -> 中 | E46: =成交明细!R14 -> 南 | F46: =成交明细!T14 -> 毛坯 | G46: =成交明细!U14 -> 146.5 | H46: =成交明细!W14 -> 12633
...

Sheet 持有vs出售测算
A1: 持有 vs 出售：N 年后的资产对比（简化模型）
A2: 出售方案：现在按估值卖出，扣折扣与交易成本后，资金按年化收益率滚存。持有方案：N 年后按变动后的房价卖出，另加 N 年净租金（未计租金再投资）。若为自住，把「月租金」理解为自住省下的房租。
A4: 参数
A5: 当前估值(万元) | B5: =本案估值!D30 -> 133.958 | C5: 引自「本案估值」中性估值
A6: 本案面积(㎡) | B6: =本案估值!C5 -> 110 | C6: 引自「本案估值」
A7: 成交折扣（相对估值让价） | B7: 0.02 | C7: 假设值：出售时通常需在目标价上再让一点
A8: 卖方交易成本 | B8: 0.01 | C8: 假设值：中介/杂费等；满五唯一可免个税、满两年免增值税，请以税务口径核实
A9: 对比年限 N（年） | B9: 3 | C9: 可改为 1~10
A10: 月租金(元) | B10: 3000 | C10: 假设值：请以贝壳/安居客同户型在租价格核实
A11: 年空置(月) | B11: 1 | C11: 假设值
A12: 物业费(元/㎡/月) | B12: 2.8 | C12: 来源：房天下小区页物业费 2.8 元/㎡·月
A13: 年维修/家电折旧(元) | B13: 3000 | C13: 假设值
A14: 卖房资金年化收益率 | B14: 0.02 | C14: 假设值：低风险理财/国债/提前还房贷（有房贷时可用房贷利率）
A16: 中间结果
A17: 年净租金(万元) | B17: =(B10*(12-B11)-B12*B6*12-B13)/10000 -> 2.6304 | C17: 毛租金 − 空置 − 物业费 − 维修
A18: 净租金收益率 | B18: =B17/B5 -> 0.019636005 | C18: 相对当前估值
A19: 出售方案 N 年后资金(万元) | B19: =B5*(1-B7)*(1-B8)*(1+B14)^B9 -> 137.92101
A20: 盈亏平衡：房价年变动率 | B20: =((1+B14)^B9-B17*B9/(B5*(1-B7)*(1-B8)))^(1/B9)-1 -> 0.0001635085 | C20: 房价年均变动高于此值 → 持有更划算；低于此值 → 现在卖更划算
A22: 情景对比
A23: 房价年变动率 | B23: N 年后房价(万元) | C23: 持有方案 N 年后资产(万元) | D23: 出售方案 N 年后资金(万元) | E23: 持有 − 出售(万元) | F23: 结论
A24: -0.06 | B24: =$B$5*(1+A24)^$B$9 -> 111.26337 | C24: =B24*(1-$B$7)*(1-$B$8)+$B$17*$B$9 -> 115.83892 | D24: =$B$19 -> 137.92101 | E24: =C24-D24 -> -22.082091 | F24: =IF(E24>0,"持有占优","出售占优") -> 出售占优
A25: -0.04 | B25: =$B$5*(1+A25)^$B$9 -> 118.51747 | C25: =B25*(1-$B$7)*(1-$B$8)+$B$17*$B$9 -> 122.87684 | D25: =$B$19 -> 137.92101 | E25: =C25-D25 -> -15.044169 | F25: =IF(E25>0,"持有占优","出售占优") -> 出售占优
A26: -0.02 | B26: =$B$5*(1+A26)^$B$9 -> 126.0802 | C26: =B26*(1-$B$7)*(1-$B$8)+$B$17*$B$9 -> 130.21421 | D26: =$B$19 -> 137.92101 | E26: =C26-D26 -> -7.7068056 | F26: =IF(E26>0,"持有占优","出售占优") -> 出售占优
A27: 0 | B27: =$B$5*(1+A27)^$B$9 -> 133.958 | C27: =B27*(1-$B$7)*(1-$B$8)+$B$17*$B$9 -> 137.85725 | D27: =$B$19 -> 137.92101 | E27: =C27-D27 -> -0.063762086 | F27: =IF(E27>0,"持有占优","出售占优") -> 出售占优
A28: 0.02 | B28: =$B$5*(1+A28)^$B$9 -> 142.1573 | C28: =B28*(1-$B$7)*(1-$B$8)+$B$17*$B$9 -> 145.81221 | D28: =$B$19 -> 137.92101 | E28: =C28-D28 -> 7.8912 | F28: =IF(E28>0,"持有占优","出售占优") -> 持有占优
A29: 0.04 | B29: =$B$5*(1+A29)^$B$9 -> 150.68453 | C29: =B29*(1-$B$7)*(1-$B$8)+$B$17*$B$9 -> 154.08533 | D29: =$B$19 -> 137.92101 | E29: =C29-D29 -> 16.164319 | F29: =IF(E29>0,"持有占优","出售占优") -> 持有占优
A31: 说明：模型未计入房贷利息（如有房贷，把 B14 改成房贷利率更贴近真实机会成本）、未计入换房/搬家成本和自住效用；只用于量化「房价要涨/跌多少才值得继续拿着」。
